2022-09-27 14:33:08 | INFO
    [LinkedInAssignDueDateUpdate: 76] --- BEGIN LINKEDIN CERTIFICATIONS CREATION (2022-09-27) ---

2022-09-27 14:33:08 | INFO
    [LinkedInAssignDueDateUpdate: 80] Retrieving data from Hubspot...
2022-09-27 14:33:08 | DEBUG
    [LinkedInAssignDueDateUpdate.hubapi: 36] "METHOD": "POST", "STATUS_CODE": "200","URL": "https://api.hubapi.com/crm/v3/objects/2-7353817/search"
NoneType: None
2022-09-27 14:33:09 | INFO
    [LinkedInAssignDueDateUpdate: 82] ... Obtained 1 instances to create certifications for.

2022-09-27 14:33:09 | INFO
    [LinkedInAssignDueDateUpdate: 84] Creating Certifications and LinkedIn URL

2022-09-27 14:33:12 | INFO
    [LinkedInAssignDueDateUpdate.aws_bucket: 41] Successful S3 put_object response. Status - 200
2022-09-27 14:33:12 | ERROR
{
"loggername" : "LinkedInAssignDueDateUpdate.pdfgenapi_linkedin_urls",
"filename": "pdfgenapi_linkedin_urls.py",
"funcName": "gather_urls",
"lineno": "112",
"module": "pdfgenapi_linkedin_urls",
"pathname": "/home/frank-quoc/ALTCO/Certificates/pdfgenapi_linkedin_urls.py,"
"message": {(sqlite3.IntegrityError) UNIQUE constraint failed: cert_id_history.hs_instance_id
[SQL: INSERT INTO cert_id_history (hs_instance_id) VALUES (?)]
[parameters: ('2837643877',)]
(Background on this error at: https://sqlalche.me/e/14/gkpj)}
}
Traceback (most recent call last):
  File "/usr/local/lib/python3.9/dist-packages/sqlalchemy/engine/base.py", line 1900, in _execute_context
    self.dialect.do_execute(
  File "/usr/local/lib/python3.9/dist-packages/sqlalchemy/engine/default.py", line 732, in do_execute
    cursor.execute(statement, parameters)
sqlite3.IntegrityError: UNIQUE constraint failed: cert_id_history.hs_instance_id

The above exception was the direct cause of the following exception:

Traceback (most recent call last):
  File "/home/frank-quoc/ALTCO/Certificates/pdfgenapi_linkedin_urls.py", line 106, in gather_urls
    self.urls['unique_certificate_id'] = self.create_cert_id()
  File "/home/frank-quoc/ALTCO/Certificates/pdfgenapi_linkedin_urls.py", line 96, in create_cert_id
    self.session.commit()
  File "<string>", line 2, in commit
  File "/usr/local/lib/python3.9/dist-packages/sqlalchemy/orm/session.py", line 1451, in commit
    self._transaction.commit(_to_root=self.future)
  File "/usr/local/lib/python3.9/dist-packages/sqlalchemy/orm/session.py", line 829, in commit
    self._prepare_impl()
  File "/usr/local/lib/python3.9/dist-packages/sqlalchemy/orm/session.py", line 808, in _prepare_impl
    self.session.flush()
  File "/usr/local/lib/python3.9/dist-packages/sqlalchemy/orm/session.py", line 3383, in flush
    self._flush(objects)
  File "/usr/local/lib/python3.9/dist-packages/sqlalchemy/orm/session.py", line 3523, in _flush
    transaction.rollback(_capture_exception=True)
  File "/usr/local/lib/python3.9/dist-packages/sqlalchemy/util/langhelpers.py", line 70, in __exit__
    compat.raise_(
  File "/usr/local/lib/python3.9/dist-packages/sqlalchemy/util/compat.py", line 208, in raise_
    raise exception
  File "/usr/local/lib/python3.9/dist-packages/sqlalchemy/orm/session.py", line 3483, in _flush
    flush_context.execute()
  File "/usr/local/lib/python3.9/dist-packages/sqlalchemy/orm/unitofwork.py", line 456, in execute
    rec.execute(self)
  File "/usr/local/lib/python3.9/dist-packages/sqlalchemy/orm/unitofwork.py", line 630, in execute
    util.preloaded.orm_persistence.save_obj(
  File "/usr/local/lib/python3.9/dist-packages/sqlalchemy/orm/persistence.py", line 245, in save_obj
    _emit_insert_statements(
  File "/usr/local/lib/python3.9/dist-packages/sqlalchemy/orm/persistence.py", line 1238, in _emit_insert_statements
    result = connection._execute_20(
  File "/usr/local/lib/python3.9/dist-packages/sqlalchemy/engine/base.py", line 1705, in _execute_20
    return meth(self, args_10style, kwargs_10style, execution_options)
  File "/usr/local/lib/python3.9/dist-packages/sqlalchemy/sql/elements.py", line 333, in _execute_on_connection
    return connection._execute_clauseelement(
  File "/usr/local/lib/python3.9/dist-packages/sqlalchemy/engine/base.py", line 1572, in _execute_clauseelement
    ret = self._execute_context(
  File "/usr/local/lib/python3.9/dist-packages/sqlalchemy/engine/base.py", line 1943, in _execute_context
    self._handle_dbapi_exception(
  File "/usr/local/lib/python3.9/dist-packages/sqlalchemy/engine/base.py", line 2124, in _handle_dbapi_exception
    util.raise_(
  File "/usr/local/lib/python3.9/dist-packages/sqlalchemy/util/compat.py", line 208, in raise_
    raise exception
  File "/usr/local/lib/python3.9/dist-packages/sqlalchemy/engine/base.py", line 1900, in _execute_context
    self.dialect.do_execute(
  File "/usr/local/lib/python3.9/dist-packages/sqlalchemy/engine/default.py", line 732, in do_execute
    cursor.execute(statement, parameters)
sqlalchemy.exc.IntegrityError: (sqlite3.IntegrityError) UNIQUE constraint failed: cert_id_history.hs_instance_id
[SQL: INSERT INTO cert_id_history (hs_instance_id) VALUES (?)]
[parameters: ('2837643877',)]
(Background on this error at: https://sqlalche.me/e/14/gkpj)
2022-09-27 14:33:12 | INFO
    [LinkedInAssignDueDateUpdate:100] 
Urls for 1 instance(s) have been created.

2022-09-27 14:33:12 | INFO
    [LinkedInAssignDueDateUpdate.hubapi:153] 1 batch request to do.
2022-09-27 14:33:12 | INFO
    [LinkedInAssignDueDateUpdate.hubapi:156] Working on batch request 1/1...
2022-09-27 14:33:12 | DEBUG
    [LinkedInAssignDueDateUpdate.hubapi: 36] "METHOD": "POST", "STATUS_CODE": "200","URL": "https://api.hubapi.com/crm/v3/objects/2-7353817/batch/update"
NoneType: None
2022-09-27 14:33:13 | INFO
    [LinkedInAssignDueDateUpdate:108] 
--- END LINKEDIN CERTIFICATIONS CREATION ---

